Workbook

Sheet README
A1: Limited Entry Calculator — Plug & Perf (SI units)
A3: WHAT IT DOES
A4: 1. Inputs — stage rate, fluid, proppant, up to 12 clusters (stress, shots, entry-hole diameter, Cd, near-wellbore coefficient).
A5: 2. SDT — fits step-down / step-rate tests: BHP − ISIP = a·Q² + b·Q^β. Gives effective perforation area A_eff = n·Cd·d² and open perforations for any assumed Cd.
A6: 3. Erosion — time-marches the pump schedule with the Long et al. erosion model (Cd rounding + diameter growth); calibrates α from pre- and post-stage SDTs.
A7: 4. Distribution — solves the common operating point: every cluster sees the same casing pressure, Σq = Q. Conceptual LE plot included.
A8: 5. Design — perforation friction matrix (shots × diameter), required shots for a target friction, start vs end-of-stage friction.
A10: HOW TO USE
A11: Edit only cells with BLUE text on a light-yellow fill (bright yellow = key switches). Everything else is a formula. Example values are a SYNTHETIC demo case — replace them.
A12: Workflow: Inputs → SDT (pre-proppant test, end-of-stage test) → Erosion (set 'Use calibrated α' = Yes once both SDTs are entered) → Distribution (State = Start / End) → Design.
A13: Clusters: set shots = 0 to switch a cluster off. Rate in m³/min, pressure in MPa, diameter in mm, proppant in kg per m³ of clean fluid.
A15: EQUATIONS (SI)
... A36: Step-down tests: Mondal et al., 'Advancements in Step Down Tests to Guide Perforation Cluster Design and Limited Entry Pressure Intensities', SPE-204147-MS, 2021.

Sheet Inputs
A1: Inputs (SI)
A2: Blue text on yellow = edit. Grey = helper formulas. Demo values are SYNTHETIC.
A3: Global
A4: Stage rate Q, m³/min | B4: 14
A5: Clean fluid density ρ, kg/m³ | B5: 1006
A6: Proppant specific gravity | B6: 2.65
A7: Initial discharge coefficient Cd0 | B7: 0.56
A8: Max discharge coefficient Cd_max | B8: 0.89
A9: Erosion α input, m²·s/kg (diameter) | B9: 3.1e-13
A10: Erosion β, m·s/kg (Cd rounding) | B10: 1e-10
A11: Near-wellbore exponent β_nwb | B11: 0.5
A12: Orifice constant K (MPa, m³/min, mm, kg/m³) | B12: =8000000/(PI()^2*3600)
A13: Use calibrated α from SDTs? (Yes/No) | B13: No
A14: α used in model, m²·s/kg | B14: =IF(B13="Yes",Erosion!B56,B9)
A15: Distribution state (Start/End of stage) | B15: Start
A16: Open perforations for erosion (Design/SDT) | B16: Design
A17: Erosion time step, min | B17: 1
A18: Active clusters | B18: =COUNTIF(D23:D34,">0")
A19: Total perforations in stage | B19: =SUMIF(D23:D34,">0")
A20: Equal share per cluster, m³/min | B20: =B4/B18
A21: Shot-weighted entry hole d0, mm | B21: =SUMPRODUCT(D23:D34,E23:E34)/B19
A22: Cluster | B22: MD, m | C22: Stress σ, MPa | D22: Shots n | E22: Entry hole d, mm | F22: Cd | G22: k_nwb, MPa/(m³/min)^β | H22: d used, mm | I22: Cd used | J22: σ (active, min) | K22: P at equal share, MPa | L22: σ (active, max)
A23: C1 heel | B23: 4572 | C23: 55.2 | D23: 6 | E23: 10.2 | F23: 0.56 | G23: 0.5 | H23: =IF($B$15="End",E23*Erosion!$B$45/$B$21,E23) | I23: =IF($B$15="End",Erosion!$B$46,F23) | J23: =IF(D23>0,C23,1000000000) | K23: =IF(D23>0,C23+$B$12*$B$5*$B$20^2/(D23^2*H23^4*I23^2)+G23*$B$20^$B$11,-1000000000) | L23: =IF(D23>0,C23,-1000000000)
A24: C2 | B24: 4584 | C24: 56.2 | D24: 6 | E24: 10.2 | F24: 0.56 | G24: 0.5 | H24: =IF($B$15="End",E24*Erosion!$B$45/$B$21,E24) | I24: =IF($B$15="End",Erosion!$B$46,F24) | J24: =IF(D24>0,C24,1000000000) | K24: =IF(D24>0,C24+$B$12*$B$5*$B$20^2/(D24^2*H24^4*I24^2)+G24*$B$20^$B$11,-1000000000) | L24: =IF(D24>0,C24,-1000000000)
A25: C3 | B25: 4596 | C25: 54.5 | D25: 6 | E25: 10.2 | F25: 0.56 | G25: 0.5 | H25: =IF($B$15="End",E25*Erosion!$B$45/$B$21,E25) | I25: =IF($B$15="End",Erosion!$B$46,F25) | J25: =IF(D25>0,C25,1000000000) | K25: =IF(D25>0,C25+$B$12*$B$5*$B$20^2/(D25^2*H25^4*I25^2)+G25*$B$20^$B$11,-1000000000) | L25: =IF(D25>0,C25,-1000000000)
A26: C4 | B26: 4608 | C26: 56.9 | D26: 6 | E26: 10.2 | F26: 0.56 | G26: 0.5 | H26: =IF($B$15="End",E26*Erosion!$B$45/$B$21,E26) | I26: =IF($B$15="End",Erosion!$B$46,F26) | J26: =IF(D26>0,C26,1000000000) | K26: =IF(D26>0,C26+$B$12*$B$5*$B$20^2/(D26^2*H26^4*I26^2)+G26*$B$20^$B$11,-1000000000) | L26: =IF(D26>0,C26,-1000000000)
A27: C5 | B27: 4620 | C27: 55.5 | D27: 6 | E27: 10.2 | F27: 0.56 | G27: 0.5 | H27: =IF($B$15="End",E27*Erosion!$B$45/$B$21,E27) | I27: =IF($B$15="End",Erosion!$B$46,F27) | J27: =IF(D27>0,C27,1000000000) | K27: =IF(D27>0,C27+$B$12*$B$5*$B$20^2/(D27^2*H27^4*I27^2)+G27*$B$20^$B$11,-1000000000) | L27: =IF(D27>0,C27,-1000000000)
A28: C6 toe | B28: 4632 | C28: 53.8 | D28: 6 | E28: 10.2 | F28: 0.56 | G28: 0.5 | H28: =IF($B$15="End",E28*Erosion!$B$45/$B$21,E28) | I28: =IF($B$15="End",Erosion!$B$46,F28) | J28: =IF(D28>0,C28,1000000000) | K28: =IF(D28>0,C28+$B$12*$B$5*$B$20^2/(D28^2*H28^4*I28^2)+G28*$B$20^$B$11,-1000000000) | L28: =IF(D28>0,C28,-1000000000)
A29: C7 | D29: 0 | E29: 10.2 | F29: 0.56 | G29: 0 | H29: =IF($B$15="End",E29*Erosion!$B$45/$B$21,E29) | I29: =IF($B$15="End",Erosion!$B$46,F29) | J29: =IF(D29>0,C29,1000000000) | K29: =IF(D29>0,C29+$B$12*$B$5*$B$20^2/(D29^2*H29^4*I29^2)+G29*$B$20^$B$11,-1000000000) | L29: =IF(D29>0,C29,-1000000000)
A30: C8 | D30: 0 | E30: 10.2 | F30: 0.56 | G30: 0 | H30: =IF($B$15="End",E30*Erosion!$B$45/$B$21,E30) | I30: =IF($B$15="End",Erosion!$B$46,F30) | J30: =IF(D30>0,C30,1000000000) | K30: =IF(D30>0,C30+$B$12*$B$5*$B$20^2/(D30^2*H30^4*I30^2)+G30*$B$20^$B$11,-1000000000) | L30: =IF(D30>0,C30,-1000000000)
A31: C9 | D31: 0 | E31: 10.2 | F31: 0.56 | G31: 0 | H31: =IF($B$15="End",E31*Erosion!$B$45/$B$21,E31) | I31: =IF($B$15="End",Erosion!$B$46,F31) | J31: =IF(D31>0,C31,1000000000) | K31: =IF(D31>0,C31+$B$12*$B$5*$B$20^2/(D31^2*H31^4*I31^2)+G31*$B$20^$B$11,-1000000000) | L31: =IF(D31>0,C31,-1000000000)
A32: C10 | D32: 0 | E32: 10.2 | F32: 0.56 | G32: 0 | H32: =IF($B$15="End",E32*Erosion!$B$45/$B$21,E32) | I32: =IF($B$15="End",Erosion!$B$46,F32) | J32: =IF(D32>0,C32,1000000000) | K32: =IF(D32>0,C32+$B$12*$B$5*$B$20^2/(D32^2*H32^4*I32^2)+G32*$B$20^$B$11,-1000000000) | L32: =IF(D32>0,C32,-1000000000)
A33: C11 | D33: 0 | E33: 10.2 | F33: 0.56 | G33: 0 | H33: =IF($B$15="End",E33*Erosion!$B$45/$B$21,E33) | I33: =IF($B$15="End",Erosion!$B$46,F33) | J33: =IF(D33>0,C33,1000000000) | K33: =IF(D33>0,C33+$B$12*$B$5*$B$20^2/(D33^2*H33^4*I33^2)+G33*$B$20^$B$11,-1000000000) | L33: =IF(D33>0,C33,-1000000000)
A34: C12 | D34: 0 | E34: 10.2 | F34: 0.56 | G34: 0 | H34: =IF($B$15="End",E34*Erosion!$B$45/$B$21,E34) | I34: =IF($B$15="End",Erosion!$B$46,F34) | J34: =IF(D34>0,C34,1000000000) | K34: =IF(D34>0,C34+$B$12*$B$5*$B$20^2/(D34^2*H34^4*I34^2)+G34*$B$20^$B$11,-1000000000) | L34: =IF(D34>0,C34,-1000000000)
A36: End state uses the lumped erosion result (Erosion sheet) for every cluster; per-cluster coupled erosion is in le_engine.py.

Sheet SDT
A1: Step-down / step-rate test analysis: BHP − ISIP = a·Q² + b·Q^β (a, b ≥ 0)
A2: Use pressures at the same time after each rate change. Pre-proppant test fixes open perforations; end-of-stage test measures erosion.
A3: Pre-proppant test (start of stage) | J3: End-of-stage test
A4: ISIP (bottomhole), MPa | B4: 57.6 | J4: ISIP (bottomhole), MPa | K4: 57.6
A5: Pressure type (BH/Surface) | B5: BH | J5: Pressure type (BH/Surface) | K5: BH
A6: TVD, m (surface only) | B6: 2900 | J6: TVD, m (surface only) | K6: 2900
A7: Pipe friction k, MPa/(m³/min)^e (surface) | B7: 0 | J7: Pipe friction k, MPa/(m³/min)^e (surface) | K7: 0
A8: Pipe friction exponent e | B8: 1.8 | J8: Pipe friction exponent e | K8: 1.8
A9: Entry hole d, mm | B9: 10.16 | J9: Entry hole d, mm | K9: 10.16
A10: Pressure noise floor, MPa | B10: 0.17 | J10: Pressure noise floor, MPa | K10: 0.17
A12: Rate, m³/min | B12: Pressure, MPa | C12: Use | D12: BHP, MPa | E12: y = BHP−ISIP | F12: x1 = Q² | G12: x2 = Q^β | H12: Fit, MPa | J12: Rate, m³/min | K12: Pressure, MPa | L12: Use | M12: BHP, MPa | N12: y = BHP−ISIP | O12: x1 = Q² | P12: x2 = Q^β | Q12: Fit, MPa
A13: 14 | B13: 74.22 | C13: =IF(AND(ISNUMBER(A13),ISNUMBER(B13)),IF(A13>0,1,0),0) | D13: =IF(C13=1,IF($B$5="Surface",B13+Inputs!$B$5*9.80665*$B$6/1000000-$B$7*A13^$B$8,B13),0) | E13: =IF(C13=1,D13-$B$4,0) | F13: =IF(C13=1,A13^2,0) | G13: =IF(C13=1,A13^Inputs!$B$11,0) | H13: =IF(C13=1,$B$36*F13+$B$37*G13,NA()) | J13: 14 | K13: 61.24 | L13: =IF(AND(ISNUMBER(J13),ISNUMBER(K13)),IF(J13>0,1,0),0) | M13: =IF(L13=1,IF($K$5="Surface",K13+Inputs!$B$5*9.80665*$K$6/1000000-$K$7*J13^$K$8,K13),0) | N13: =IF(L13=1,M13-$K$4,0) | O13: =IF(L13=1,J13^2,0) | P13: =IF(L13=1,J13^Inputs!$B$11,0) | Q13: =IF(L13=1,$K$36*O13+$K$37*P13,NA())
A14: 11 | B14: 68.24 | C14: =IF(AND(ISNUMBER(A14),ISNUMBER(B14)),IF(A14>0,1,0),0) | D14: =IF(C14=1,IF($B$5="Surface",B14+Inputs!$B$5*9.80665*$B$6/1000000-$B$7*A14^$B$8,B14),0) | E14: =IF(C14=1,D14-$B$4,0) | F14: =IF(C14=1,A14^2,0) | G14: =IF(C14=1,A14^Inputs!$B$11,0) | H14: =IF(C14=1,$B$36*F14+$B$37*G14,NA()) | J14: 11 | K14: 60.09 | L14: =IF(AND(ISNUMBER(J14),ISNUMBER(K14)),IF(J14>0,1,0),0) | M14: =IF(L14=1,IF($K$5="Surface",K14+Inputs!$B$5*9.80665*$K$6/1000000-$K$7*J14^$K$8,K14),0) | N14: =IF(L14=1,M14-$K$4,0) | O14: =IF(L14=1,J14^2,0) | P14: =IF(L14=1,J14^Inputs!$B$11,0) | Q14: =IF(L14=1,$K$36*O14+$K$37*P14,NA())
A15: 8 | B15: 63.9 | C15: =IF(AND(ISNUMBER(A15),ISNUMBER(B15)),IF(A15>0,1,0),0) | D15: =IF(C15=1,IF($B$5="Surface",B15+Inputs!$B$5*9.80665*$B$6/1000000-$B$7*A15^$B$8,B15),0) | E15: =IF(C15=1,D15-$B$4,0) | F15: =IF(C15=1,A15^2,0) | G15: =IF(C15=1,A15^Inputs!$B$11,0) | H15: =IF(C15=1,$B$36*F15+$B$37*G15,NA()) | J15: 8 | K15: 59.27 | L15: =IF(AND(ISNUMBER(J15),ISNUMBER(K15)),IF(J15>0,1,0),0) | M15: =IF(L15=1,IF($K$5="Surface",K15+Inputs!$B$5*9.80665*$K$6/1000000-$K$7*J15^$K$8,K15),0) | N15: =IF(L15=1,M15-$K$4,0) | O15: =IF(L15=1,J15^2,0) | P15: =IF(L15=1,J15^Inputs!$B$11,0) | Q15: =IF(L15=1,$K$36*O15+$K$37*P15,NA())
A16: 5 | B16: 60.69 | C16: =IF(AND(ISNUMBER(A16),ISNUMBER(B16)),IF(A16>0,1,0),0) | D16: =IF(C16=1,IF($B$5="Surface",B16+Inputs!$B$5*9.80665*$B$6/1000000-$B$7*A16^$B$8,B16),0) | E16: =IF(C16=1,D16-$B$4,0) | F16: =IF(C16=1,A16^2,0) | G16: =IF(C16=1,A16^Inputs!$B$11,0) | H16: =IF(C16=1,$B$36*F16+$B$37*G16,NA()) | J16: 5 | K16: 58.5 | L16: =IF(AND(ISNUMBER(J16),ISNUMBER(K16)),IF(J16>0,1,0),0) | M16: =IF(L16=1,IF($K$5="Surface",K16+Inputs!$B$5*9.80665*$K$6/1000000-$K$7*J16^$K$8,K16),0) | N16: =IF(L16=1,M16-$K$4,0) | O16: =IF(L16=1,J16^2,0) | P16: =IF(L16=1,J16^Inputs!$B$11,0) | Q16: =IF(L16=1,$K$36*O16+$K$37*P16,NA())
C17: =IF(AND(ISNUMBER(A17),ISNUMBER(B17)),IF(A17>0,1,0),0) | D17: =IF(C17=1,IF($B$5="Surface",B17+Inputs!$B$5*9.80665*$B$6/1000000-$B$7*A17^$B$8,B17),0) | E17: =IF(C17=1,D17-$B$4,0) | F17: =IF(C17=1,A17^2,0) | G17: =IF(C17=1,A17^Inputs!$B$11,0) | H17: =IF(C17=1,$B$36*F17+$B$37*G17,NA()) | L17: =IF(AND(ISNUMBER(J17),ISNUMBER(K17)),IF(J17>0,1,0),0) | M17: =IF(L17=1,IF($K$5="Surface",K17+Inputs!$B$5*9.80665*$K$6/1000000-$K$7*J17^$K$8,K17),0) | N17: =IF(L17=1,M17-$K$4,0) | O17: =IF(L17=1,J17^2,0) | P17: =IF(L17=1,J17^Inputs!$B$11,0) | Q17: =IF(L17=1,$K$36*O17+$K$37*P17,NA())
C18: =IF(AND(ISNUMBER(A18),ISNUMBER(B18)),IF(A18>0,1,0),0) | D18: =IF(C18=1,IF($B$5="Surface",B18+Inputs!$B$5*9.80665*$B$6/1000000-$B$7*A18^$B$8,B18),0) | E18: =IF(C18=1,D18-$B$4,0) | F18: =IF(C18=1,A18^2,0) | G18: =IF(C18=1,A18^Inputs!$B$11,0) | H18: =IF(C18=1,$B$36*F18+$B$37*G18,NA()) | L18: =IF(AND(ISNUMBER(J18),ISNUMBER(K18)),IF(J18>0,1,0),0) | M18: =IF(L18=1,IF($K$5="Surface",K18+Inputs!$B$5*9.80665*$K$6/1000000-$K$7*J18^$K$8,K18),0) | N18: =IF(L18=1,M18-$K$4,0) | O18: =IF(L18=1,J18^2,0) | P18: =IF(L18=1,J18^Inputs!$B$11,0) | Q18: =IF(L18=1,$K$36*O18+$K$37*P18,NA())
C19: =IF(AND(ISNUMBER(A19),ISNUMBER(B19)),IF(A19>0,1,0),0) | D19: =IF(C19=1,IF($B$5="Surface",B19+Inputs!$B$5*9.80665*$B$6/1000000-$B$7*A19^$B$8,B19),0) | E19: =IF(C19=1,D19-$B$4,0) | F19: =IF(C19=1,A19^2,0) | G19: =IF(C19=1,A19^Inputs!$B$11,0) | H19: =IF(C19=1,$B$36*F19+$B$37*G19,NA()) | L19: =IF(AND(ISNUMBER(J19),ISNUMBER(K19)),IF(J19>0,1,0),0) | M19: =IF(L19=1,IF($K$5="Surface",K19+Inputs!$B$5*9.80665*$K$6/1000000-$K$7*J19^$K$8,K19),0) | N19: =IF(L19=1,M19-$K$4,0) | O19: =IF(L19=1,J19^2,0) | P19: =IF(L19=1,J19^Inputs!$B$11,0) | Q19: =IF(L19=1,$K$36*O19+$K$37*P19,NA())
C20: =IF(AND(ISNUMBER(A20),ISNUMBER(B20)),IF(A20>0,1,0),0) | D20: =IF(C20=1,IF($B$5="Surface",B20+Inputs!$B$5*9.80665*$B$6/1000000-$B$7*A20^$B$8,B20),0) | E20: =IF(C20=1,D20-$B$4,0) | F20: =IF(C20=1,A20^2,0) | G20: =IF(C20=1,A20^Inputs!$B$11,0) | H20: =IF(C20=1,$B$36*F20+$B$37*G20,NA()) | L20: =IF(AND(ISNUMBER(J20),ISNUMBER(K20)),IF(J20>0,1,0),0) | M20: =IF(L20=1,IF($K$5="Surface",K20+Inputs!$B$5*9.80665*$K$6/1000000-$K$7*J20^$K$8,K20),0) | N20: =IF(L20=1,M20-$K$4,0) | O20: =IF(L20=1,J20^2,0) | P20: =IF(L20=1,J20^Inputs!$B$11,0) | Q20: =IF(L20=1,$K$36*O20+$K$37*P20,NA())
C21: =IF(AND(ISNUMBER(A21),ISNUMBER(B21)),IF(A21>0,1,0),0) | D21: =IF(C21=1,IF($B$5="Surface",B21+Inputs!$B$5*9.80665*$B$6/1000000-$B$7*A21^$B$8,B21),0) | E21: =IF(C21=1,D21-$B$4,0) | F21: =IF(C21=1,A21^2,0) | G21: =IF(C21=1,A21^Inputs!$B$11,0) | H21: =IF(C21=1,$B$36*F21+$B$37*G21,NA()) | L21: =IF(AND(ISNUMBER(J21),ISNUMBER(K21)),IF(J21>0,1,0),0) | M21: =IF(L21=1,IF($K$5="Surface",K21+Inputs!$B$5*9.80665*$K$6/1000000-$K$7*J21^$K$8,K21),0) | N21: =IF(L21=1,M21-$K$4,0) | O21: =IF(L21=1,J21^2,0) | P21: =IF(L21=1,J21^Inputs!$B$11,0) | Q21: =IF(L21=1,$K$36*O21+$K$37*P21,NA())
C22: =IF(AND(ISNUMBER(A22),ISNUMBER(B22)),IF(A22>0,1,0),0) | D22: =IF(C22=1,IF($B$5="Surface",B22+Inputs!$B$5*9.80665*$B$6/1000000-$B$7*A22^$B$8,B22),0) | E22: =IF(C22=1,D22-$B$4,0) | F22: =IF(C22=1,A22^2,0) | G22: =IF(C22=1,A22^Inputs!$B$11,0) | H22: =IF(C22=1,$B$36*F22+$B$37*G22,NA()) | L22: =IF(AND(ISNUMBER(J22),ISNUMBER(K22)),IF(J22>0,1,0),0) | M22: =IF(L22=1,IF($K$5="Surface",K22+Inputs!$B$5*9.80665*$K$6/1000000-$K$7*J22^$K$8,K22),0) | N22: =IF(L22=1,M22-$K$4,0) | O22: =IF(L22=1,J22^2,0) | P22: =IF(L22=1,J22^Inputs!$B$11,0) | Q22: =IF(L22=1,$K$36*O22+$K$37*P22,NA())
A25: S11 = Σx1² | B25: =SUMPRODUCT(F13:F22,F13:F22) | J25: S11 = Σx1² | K25: =SUMPRODUCT(O13:O22,O13:O22)
A26: S12 = Σx1·x2 | B26: =SUMPRODUCT(F13:F22,G13:G22) | J26: S12 = Σx1·x2 | K26: =SUMPRODUCT(O13:O22,P13:P22)
A27: S22 = Σx2² | B27: =SUMPRODUCT(G13:G22,G13:G22) | J27: S22 = Σx2² | K27: =SUMPRODUCT(P13:P22,P13:P22)
A28: T1 = Σx1·y | B28: =SUMPRODUCT(F13:F22,E13:E22) | J28: T1 = Σx1·y | K28: =SUMPRODUCT(O13:O22,N13:N22)
A29: T2 = Σx2·y | B29: =SUMPRODUCT(G13:G22,E13:E22) | J29: T2 = Σx2·y | K29: =SUMPRODUCT(P13:P22,N13:N22)
A30: det | B30: =B25*B27-B26^2 | J30: det | K30: =K25*K27-K26^2
A31: a (two-term) | B31: =IF(B30=0,-1,(B28*B27-B29*B26)/B30) | J31: a (two-term) | K31: =IF(K30=0,-1,(K28*K27-K29*K26)/K30)
A32: b (two-term) | B32: =IF(B30=0,-1,(B25*B29-B26*B28)/B30) | J32: b (two-term) | K32: =IF(K30=0,-1,(K25*K29-K26*K28)/K30)
A33: a (perforations only) | B33: =IF(B25>0,MAX(0,B28/B25),0) | J33: a (perforations only) | K33: =IF(K25>0,MAX(0,K28/K25),0)
A34: b (near-wellbore only) | B34: =IF(B27>0,MAX(0,B29/B27),0) | J34: b (near-wellbore only) | K34: =IF(K27>0,MAX(0,K29/K27),0)
A35: Model used | B35: =IF(AND(B31>=0,B32>=0),"two-term",IF(B33>0,"perforations only","near-wellbore only")) | J35: Model used | K35: =IF(AND(K31>=0,K32>=0),"two-term",IF(K33>0,"perforations only","near-wellbore only"))
A36: a, MPa/(m³/min)² | B36: =IF(B35="two-term",B31,IF(B35="perforations only",B33,0)) | J36: a, MPa/(m³/min)² | K36: =IF(K35="two-term",K31,IF(K35="perforations only",K33,0))
A37: b, MPa/(m³/min)^β | B37: =IF(B35="two-term",B32,IF(B35="near-wellbore only",B34,0)) | J37: b, MPa/(m³/min)^β | K37: =IF(K35="two-term",K32,IF(K35="near-wellbore only",K34,0))
A38: RMSE, MPa | B38: =SQRT(SUMPRODUCT(C13:C22,(E13:E22-$B$36*F13:F22-$B$37*G13:G22)^2)/SUM(C13:C22)) | J38: RMSE, MPa | K38: =SQRT(SUMPRODUCT(L13:L22,(N13:N22-$K$36*O13:O22-$K$37*P13:P22)^2)/SUM(L13:L22))
A39: Max rate, m³/min | B39: =MAX(A13:A22) | J39: Max rate, m³/min | K39: =MAX(J13:J22)
A40: ΔP_perf at max rate, MPa | B40: =B36*B39^2 | J40: ΔP_perf at max rate, MPa | K40: =K36*K39^2
A41: ΔP_nwb at max rate, MPa | B41: =B37*B39^Inputs!$B$11 | J41: ΔP_nwb at max rate, MPa | K41: =K37*K39^Inputs!$B$11
A42: Resolvable? (ΔP_perf > 4 × noise) | B42: =IF(B40>4*MAX(B38,B10),"YES","NO — perf friction lost in noise") | J42: Resolvable? (ΔP_perf > 4 × noise) | K42: =IF(K40>4*MAX(K38,K10),"YES","NO — perf friction lost in noise")
A43: A_eff = n·Cd·d², mm² | B43: =IF(B36>0,SQRT(Inputs!$B$12*Inputs!$B$5/B36),"∞") | J43: A_eff = n·Cd·d², mm² | K43: =IF(K36>0,SQRT(Inputs!$B$12*Inputs!$B$5/K36),"∞")
...

Sheet Erosion
A1: Perforation erosion through the pump schedule (lumped, Long et al. 2018)
A3: Open perforations n | B3: =IF(Inputs!B16="SDT",SDT!B72,Inputs!B19)
A4: Initial diameter d0, mm | B4: =Inputs!B21
A5: Cd0 | B5: =Inputs!B7
A6: Cd_max | B6: =Inputs!B8
A7: α used, m²·s/kg | B7: =Inputs!B14
A8: β, m·s/kg | B8: =Inputs!B10
A9: Time step, min | B9: =Inputs!B17
A10: Fluid density, kg/m³ | B10: =Inputs!B5
A11: Proppant SG | B11: =Inputs!B6
A12: Total pumping time, min | B12: =SUM(B16:B35)
A15: Step | B15: Duration, min | C15: Rate, m³/min | D15: Proppant, kg/m³ clean | E15: Start time, min
A16: 1 | B16: 10 | C16: 14 | D16: 0 | E16: =0
A17: 2 | B17: 20 | C17: 14 | D17: 60 | E17: =E16+N(B16)
A18: 3 | B18: 20 | C18: 14 | D18: 120 | E18: =E17+N(B17)
A19: 4 | B19: 20 | C19: 14 | D19: 180 | E19: =E18+N(B18)
A20: 5 | B20: 20 | C20: 14 | D20: 240 | E20: =E19+N(B19)
A21: 6 | B21: 20 | C21: 14 | D21: 240 | E21: =E20+N(B20)
A22: 7 | B22: 5 | C22: 14 | D22: 0 | E22: =E21+N(B21)
A23: 8 | E23: =E22+N(B22)
A24: 9 | E24: =E23+N(B23)
A25: 10 | E25: =E24+N(B24)
A26: 11 | E26: =E25+N(B25)
A27: 12 | E27: =E26+N(B26)
A28: 13 | E28: =E27+N(B27)
A29: 14 | E29: =E28+N(B28)
A30: 15 | E30: =E29+N(B29)
A31: 16 | E31: =E30+N(B30)
A32: 17 | E32: =E31+N(B31)
A33: 18 | E33: =E32+N(B32)
A34: 19 | E34: =E33+N(B33)
A35: 20 | E35: =E34+N(B34)
A41: Summary
A42: Active time rows | B42: =SUM(C61:C420)
A43: ΔP_perf at start, MPa | B43: =O61
A44: ΔP_perf at end, MPa | B44: =INDEX(O61:O420,B42)
A45: D at end, mm | B45: =INDEX(M61:M420,B42)
A46: Cd at end | B46: =INDEX(N61:N420,B42)
A47: Friction retained | B47: =B44/B43
A48: Proppant per perforation, kg | B48: =INDEX(P61:P420,B42)
...

Sheet Distribution
A1: Flow distribution — common operating point (Σq = Q, equal casing pressure)
A3: Min active stress, MPa | B3: =MIN(Inputs!J23:J34) | D3: Cluster | E3: σ, MPa | F3: Shots | G3: q raw | H3: q, m³/min | I3: Share | J3: ΔP_perf, MPa | K3: ΔP_nwb, MPa | L3: vs equal share | M3: q (active only)
A4: Max P at equal share, MPa | B4: =MAX(Inputs!K23:K34) | D4: =Inputs!A23 | E4: =Inputs!C23 | F4: =Inputs!D23 | G4: =IF(Inputs!$D$23=0,0,IF($B$9<=Inputs!$C$23,0,IF($B$9>=INDEX(LE_Curves!$C$5:$C$205,201),INDEX(LE_Curves!$B$5:$B$205,201),INDEX(LE_Curves!$B$5:$B$205,MATCH($B$9,LE_Curves!$C$5:$C$205,1))+($B$9-INDEX(LE_Curves!$C$5:$C$205,MATCH($B$9,LE_Curves!$C$5:$C$205,1)))*(INDEX(LE_Curves!$B$5:$B$205,MATCH($B$9,LE_Curves!$C$5:$C$205,1)+1)-INDEX(LE_Curves!$B$5:$B$205,MATCH($B$9,LE_Curves!$C$5:$C$205,1)))/(INDEX(LE_Curves!$C$5:$C$205,MATCH($B$9,LE_Curves!$C$5:$C$205,1)+1)-INDEX(LE_Curves!$C$5:$C$205,MATCH($B$9,LE_Curves!$C$5:$C$205,1)))))) | H4: =G4*Inputs!$B$4/$B$10 | I4: =H4/Inputs!$B$4 | J4: =IF(F4>0,Inputs!$B$12*Inputs!$B$5*H4^2/(F4^2*Inputs!H23^4*Inputs!I23^2),0) | K4: =IF(F4>0,Inputs!G23*H4^Inputs!$B$11,0) | L4: =IF(F4>0,H4/Inputs!$B$20-1,0) | M4: =IF(F4>0,H4,1000000000)
A5: Coarse bracket index | B5: =MIN(MATCH(Inputs!B4,O31:O231,1),200) | D5: =Inputs!A24 | E5: =Inputs!C24 | F5: =Inputs!D24 | G5: =IF(Inputs!$D$24=0,0,IF($B$9<=Inputs!$C$24,0,IF($B$9>=INDEX(LE_Curves!$D$5:$D$205,201),INDEX(LE_Curves!$B$5:$B$205,201),INDEX(LE_Curves!$B$5:$B$205,MATCH($B$9,LE_Curves!$D$5:$D$205,1))+($B$9-INDEX(LE_Curves!$D$5:$D$205,MATCH($B$9,LE_Curves!$D$5:$D$205,1)))*(INDEX(LE_Curves!$B$5:$B$205,MATCH($B$9,LE_Curves!$D$5:$D$205,1)+1)-INDEX(LE_Curves!$B$5:$B$205,MATCH($B$9,LE_Curves!$D$5:$D$205,1)))/(INDEX(LE_Curves!$D$5:$D$205,MATCH($B$9,LE_Curves!$D$5:$D$205,1)+1)-INDEX(LE_Curves!$D$5:$D$205,MATCH($B$9,LE_Curves!$D$5:$D$205,1)))))) | H5: =G5*Inputs!$B$4/$B$10 | I5: =H5/Inputs!$B$4 | J5: =IF(F5>0,Inputs!$B$12*Inputs!$B$5*H5^2/(F5^2*Inputs!H24^4*Inputs!I24^2),0) | K5: =IF(F5>0,Inputs!G24*H5^Inputs!$B$11,0) | L5: =IF(F5>0,H5/Inputs!$B$20-1,0) | M5: =IF(F5>0,H5,1000000000)
A6: Bracket P low, MPa | B6: =INDEX(B31:B231,B5) | D6: =Inputs!A25 | E6: =Inputs!C25 | F6: =Inputs!D25 | G6: =IF(Inputs!$D$25=0,0,IF($B$9<=Inputs!$C$25,0,IF($B$9>=INDEX(LE_Curves!$E$5:$E$205,201),INDEX(LE_Curves!$B$5:$B$205,201),INDEX(LE_Curves!$B$5:$B$205,MATCH($B$9,LE_Curves!$E$5:$E$205,1))+($B$9-INDEX(LE_Curves!$E$5:$E$205,MATCH($B$9,LE_Curves!$E$5:$E$205,1)))*(INDEX(LE_Curves!$B$5:$B$205,MATCH($B$9,LE_Curves!$E$5:$E$205,1)+1)-INDEX(LE_Curves!$B$5:$B$205,MATCH($B$9,LE_Curves!$E$5:$E$205,1)))/(INDEX(LE_Curves!$E$5:$E$205,MATCH($B$9,LE_Curves!$E$5:$E$205,1)+1)-INDEX(LE_Curves!$E$5:$E$205,MATCH($B$9,LE_Curves!$E$5:$E$205,1)))))) | H6: =G6*Inputs!$B$4/$B$10 | I6: =H6/Inputs!$B$4 | J6: =IF(F6>0,Inputs!$B$12*Inputs!$B$5*H6^2/(F6^2*Inputs!H25^4*Inputs!I25^2),0) | K6: =IF(F6>0,Inputs!G25*H6^Inputs!$B$11,0) | L6: =IF(F6>0,H6/Inputs!$B$20-1,0) | M6: =IF(F6>0,H6,1000000000)
A7: Bracket P high, MPa | B7: =INDEX(B31:B231,B5+1) | D7: =Inputs!A26 | E7: =Inputs!C26 | F7: =Inputs!D26 | G7: =IF(Inputs!$D$26=0,0,IF($B$9<=Inputs!$C$26,0,IF($B$9>=INDEX(LE_Curves!$F$5:$F$205,201),INDEX(LE_Curves!$B$5:$B$205,201),INDEX(LE_Curves!$B$5:$B$205,MATCH($B$9,LE_Curves!$F$5:$F$205,1))+($B$9-INDEX(LE_Curves!$F$5:$F$205,MATCH($B$9,LE_Curves!$F$5:$F$205,1)))*(INDEX(LE_Curves!$B$5:$B$205,MATCH($B$9,LE_Curves!$F$5:$F$205,1)+1)-INDEX(LE_Curves!$B$5:$B$205,MATCH($B$9,LE_Curves!$F$5:$F$205,1)))/(INDEX(LE_Curves!$F$5:$F$205,MATCH($B$9,LE_Curves!$F$5:$F$205,1)+1)-INDEX(LE_Curves!$F$5:$F$205,MATCH($B$9,LE_Curves!$F$5:$F$205,1)))))) | H7: =G7*Inputs!$B$4/$B$10 | I7: =H7/Inputs!$B$4 | J7: =IF(F7>0,Inputs!$B$12*Inputs!$B$5*H7^2/(F7^2*Inputs!H26^4*Inputs!I26^2),0) | K7: =IF(F7>0,Inputs!G26*H7^Inputs!$B$11,0) | L7: =IF(F7>0,H7/Inputs!$B$20-1,0) | M7: =IF(F7>0,H7,1000000000)
A8: Fine bracket index | B8: =MIN(MATCH(Inputs!B4,AE31:AE231,1),200) | D8: =Inputs!A27 | E8: =Inputs!C27 | F8: =Inputs!D27 | G8: =IF(Inputs!$D$27=0,0,IF($B$9<=Inputs!$C$27,0,IF($B$9>=INDEX(LE_Curves!$G$5:$G$205,201),INDEX(LE_Curves!$B$5:$B$205,201),INDEX(LE_Curves!$B$5:$B$205,MATCH($B$9,LE_Curves!$G$5:$G$205,1))+($B$9-INDEX(LE_Curves!$G$5:$G$205,MATCH($B$9,LE_Curves!$G$5:$G$205,1)))*(INDEX(LE_Curves!$B$5:$B$205,MATCH($B$9,LE_Curves!$G$5:$G$205,1)+1)-INDEX(LE_Curves!$B$5:$B$205,MATCH($B$9,LE_Curves!$G$5:$G$205,1)))/(INDEX(LE_Curves!$G$5:$G$205,MATCH($B$9,LE_Curves!$G$5:$G$205,1)+1)-INDEX(LE_Curves!$G$5:$G$205,MATCH($B$9,LE_Curves!$G$5:$G$205,1)))))) | H8: =G8*Inputs!$B$4/$B$10 | I8: =H8/Inputs!$B$4 | J8: =IF(F8>0,Inputs!$B$12*Inputs!$B$5*H8^2/(F8^2*Inputs!H27^4*Inputs!I27^2),0) | K8: =IF(F8>0,Inputs!G27*H8^Inputs!$B$11,0) | L8: =IF(F8>0,H8/Inputs!$B$20-1,0) | M8: =IF(F8>0,H8,1000000000)
A9: Operating pressure P*, MPa | B9: =IF(INDEX(AE31:AE231,B8+1)=INDEX(AE31:AE231,B8),INDEX(R31:R231,B8),INDEX(R31:R231,B8)+(Inputs!B4-INDEX(AE31:AE231,B8))*(INDEX(R31:R231,B8+1)-INDEX(R31:R231,B8))/(INDEX(AE31:AE231,B8+1)-INDEX(AE31:AE231,B8))) | D9: =Inputs!A28 | E9: =Inputs!C28 | F9: =Inputs!D28 | G9: =IF(Inputs!$D$28=0,0,IF($B$9<=Inputs!$C$28,0,IF($B$9>=INDEX(LE_Curves!$H$5:$H$205,201),INDEX(LE_Curves!$B$5:$B$205,201),INDEX(LE_Curves!$B$5:$B$205,MATCH($B$9,LE_Curves!$H$5:$H$205,1))+($B$9-INDEX(LE_Curves!$H$5:$H$205,MATCH($B$9,LE_Curves!$H$5:$H$205,1)))*(INDEX(LE_Curves!$B$5:$B$205,MATCH($B$9,LE_Curves!$H$5:$H$205,1)+1)-INDEX(LE_Curves!$B$5:$B$205,MATCH($B$9,LE_Curves!$H$5:$H$205,1)))/(INDEX(LE_Curves!$H$5:$H$205,MATCH($B$9,LE_Curves!$H$5:$H$205,1)+1)-INDEX(LE_Curves!$H$5:$H$205,MATCH($B$9,LE_Curves!$H$5:$H$205,1)))))) | H9: =G9*Inputs!$B$4/$B$10 | I9: =H9/Inputs!$B$4 | J9: =IF(F9>0,Inputs!$B$12*Inputs!$B$5*H9^2/(F9^2*Inputs!H28^4*Inputs!I28^2),0) | K9: =IF(F9>0,Inputs!G28*H9^Inputs!$B$11,0) | L9: =IF(F9>0,H9/Inputs!$B$20-1,0) | M9: =IF(F9>0,H9,1000000000)
A10: Σq before normalisation, m³/min | B10: =SUM(G4:G15) | D10: =Inputs!A29 | E10: =Inputs!C29 | F10: =Inputs!D29 | G10: =IF(Inputs!$D$29=0,0,IF($B$9<=Inputs!$C$29,0,IF($B$9>=INDEX(LE_Curves!$I$5:$I$205,201),INDEX(LE_Curves!$B$5:$B$205,201),INDEX(LE_Curves!$B$5:$B$205,MATCH($B$9,LE_Curves!$I$5:$I$205,1))+($B$9-INDEX(LE_Curves!$I$5:$I$205,MATCH($B$9,LE_Curves!$I$5:$I$205,1)))*(INDEX(LE_Curves!$B$5:$B$205,MATCH($B$9,LE_Curves!$I$5:$I$205,1)+1)-INDEX(LE_Curves!$B$5:$B$205,MATCH($B$9,LE_Curves!$I$5:$I$205,1)))/(INDEX(LE_Curves!$I$5:$I$205,MATCH($B$9,LE_Curves!$I$5:$I$205,1)+1)-INDEX(LE_Curves!$I$5:$I$205,MATCH($B$9,LE_Curves!$I$5:$I$205,1)))))) | H10: =G10*Inputs!$B$4/$B$10 | I10: =H10/Inputs!$B$4 | J10: =IF(F10>0,Inputs!$B$12*Inputs!$B$5*H10^2/(F10^2*Inputs!H29^4*Inputs!I29^2),0) | K10: =IF(F10>0,Inputs!G29*H10^Inputs!$B$11,0) | L10: =IF(F10>0,H10/Inputs!$B$20-1,0) | M10: =IF(F10>0,H10,1000000000)
A11: Uniformity index 1 − CoV | B11: =1-SQRT(SUMPRODUCT((Inputs!D23:D34>0)*(H4:H15-Inputs!B20)^2)/Inputs!B18)/Inputs!B20 | D11: =Inputs!A30 | E11: =Inputs!C30 | F11: =Inputs!D30 | G11: =IF(Inputs!$D$30=0,0,IF($B$9<=Inputs!$C$30,0,IF($B$9>=INDEX(LE_Curves!$J$5:$J$205,201),INDEX(LE_Curves!$B$5:$B$205,201),INDEX(LE_Curves!$B$5:$B$205,MATCH($B$9,LE_Curves!$J$5:$J$205,1))+($B$9-INDEX(LE_Curves!$J$5:$J$205,MATCH($B$9,LE_Curves!$J$5:$J$205,1)))*(INDEX(LE_Curves!$B$5:$B$205,MATCH($B$9,LE_Curves!$J$5:$J$205,1)+1)-INDEX(LE_Curves!$B$5:$B$205,MATCH($B$9,LE_Curves!$J$5:$J$205,1)))/(INDEX(LE_Curves!$J$5:$J$205,MATCH($B$9,LE_Curves!$J$5:$J$205,1)+1)-INDEX(LE_Curves!$J$5:$J$205,MATCH($B$9,LE_Curves!$J$5:$J$205,1)))))) | H11: =G11*Inputs!$B$4/$B$10 | I11: =H11/Inputs!$B$4 | J11: =IF(F11>0,Inputs!$B$12*Inputs!$B$5*H11^2/(F11^2*Inputs!H30^4*Inputs!I30^2),0) | K11: =IF(F11>0,Inputs!G30*H11^Inputs!$B$11,0) | L11: =IF(F11>0,H11/Inputs!$B$20-1,0) | M11: =IF(F11>0,H11,1000000000)
A12: Cluster efficiency (≥50% of equal share) | B12: =SUMPRODUCT((Inputs!D23:D34>0)*(H4:H15>=0.5*Inputs!B20))/Inputs!B18 | D12: =Inputs!A31 | E12: =Inputs!C31 | F12: =Inputs!D31 | G12: =IF(Inputs!$D$31=0,0,IF($B$9<=Inputs!$C$31,0,IF($B$9>=INDEX(LE_Curves!$K$5:$K$205,201),INDEX(LE_Curves!$B$5:$B$205,201),INDEX(LE_Curves!$B$5:$B$205,MATCH($B$9,LE_Curves!$K$5:$K$205,1))+($B$9-INDEX(LE_Curves!$K$5:$K$205,MATCH($B$9,LE_Curves!$K$5:$K$205,1)))*(INDEX(LE_Curves!$B$5:$B$205,MATCH($B$9,LE_Curves!$K$5:$K$205,1)+1)-INDEX(LE_Curves!$B$5:$B$205,MATCH($B$9,LE_Curves!$K$5:$K$205,1)))/(INDEX(LE_Curves!$K$5:$K$205,MATCH($B$9,LE_Curves!$K$5:$K$205,1)+1)-INDEX(LE_Curves!$K$5:$K$205,MATCH($B$9,LE_Curves!$K$5:$K$205,1)))))) | H12: =G12*Inputs!$B$4/$B$10 | I12: =H12/Inputs!$B$4 | J12: =IF(F12>0,Inputs!$B$12*Inputs!$B$5*H12^2/(F12^2*Inputs!H31^4*Inputs!I31^2),0) | K12: =IF(F12>0,Inputs!G31*H12^Inputs!$B$11,0) | L12: =IF(F12>0,H12/Inputs!$B$20-1,0) | M12: =IF(F12>0,H12,1000000000)
A13: Max / min cluster rate | B13: =MAX(H4:H15)/MIN(M4:M15) | D13: =Inputs!A32 | E13: =Inputs!C32 | F13: =Inputs!D32 | G13: =IF(Inputs!$D$32=0,0,IF($B$9<=Inputs!$C$32,0,IF($B$9>=INDEX(LE_Curves!$L$5:$L$205,201),INDEX(LE_Curves!$B$5:$B$205,201),INDEX(LE_Curves!$B$5:$B$205,MATCH($B$9,LE_Curves!$L$5:$L$205,1))+($B$9-INDEX(LE_Curves!$L$5:$L$205,MATCH($B$9,LE_Curves!$L$5:$L$205,1)))*(INDEX(LE_Curves!$B$5:$B$205,MATCH($B$9,LE_Curves!$L$5:$L$205,1)+1)-INDEX(LE_Curves!$B$5:$B$205,MATCH($B$9,LE_Curves!$L$5:$L$205,1)))/(INDEX(LE_Curves!$L$5:$L$205,MATCH($B$9,LE_Curves!$L$5:$L$205,1)+1)-INDEX(LE_Curves!$L$5:$L$205,MATCH($B$9,LE_Curves!$L$5:$L$205,1)))))) | H13: =G13*Inputs!$B$4/$B$10 | I13: =H13/Inputs!$B$4 | J13: =IF(F13>0,Inputs!$B$12*Inputs!$B$5*H13^2/(F13^2*Inputs!H32^4*Inputs!I32^2),0) | K13: =IF(F13>0,Inputs!G32*H13^Inputs!$B$11,0) | L13: =IF(F13>0,H13/Inputs!$B$20-1,0) | M13: =IF(F13>0,H13,1000000000)
A14: State | B14: =Inputs!B15 | D14: =Inputs!A33 | E14: =Inputs!C33 | F14: =Inputs!D33 | G14: =IF(Inputs!$D$33=0,0,IF($B$9<=Inputs!$C$33,0,IF($B$9>=INDEX(LE_Curves!$M$5:$M$205,201),INDEX(LE_Curves!$B$5:$B$205,201),INDEX(LE_Curves!$B$5:$B$205,MATCH($B$9,LE_Curves!$M$5:$M$205,1))+($B$9-INDEX(LE_Curves!$M$5:$M$205,MATCH($B$9,LE_Curves!$M$5:$M$205,1)))*(INDEX(LE_Curves!$B$5:$B$205,MATCH($B$9,LE_Curves!$M$5:$M$205,1)+1)-INDEX(LE_Curves!$B$5:$B$205,MATCH($B$9,LE_Curves!$M$5:$M$205,1)))/(INDEX(LE_Curves!$M$5:$M$205,MATCH($B$9,LE_Curves!$M$5:$M$205,1)+1)-INDEX(LE_Curves!$M$5:$M$205,MATCH($B$9,LE_Curves!$M$5:$M$205,1)))))) | H14: =G14*Inputs!$B$4/$B$10 | I14: =H14/Inputs!$B$4 | J14: =IF(F14>0,Inputs!$B$12*Inputs!$B$5*H14^2/(F14^2*Inputs!H33^4*Inputs!I33^2),0) | K14: =IF(F14>0,Inputs!G33*H14^Inputs!$B$11,0) | L14: =IF(F14>0,H14/Inputs!$B$20-1,0) | M14: =IF(F14>0,H14,1000000000)
D15: =Inputs!A34 | E15: =Inputs!C34 | F15: =Inputs!D34 | G15: =IF(Inputs!$D$34=0,0,IF($B$9<=Inputs!$C$34,0,IF($B$9>=INDEX(LE_Curves!$N$5:$N$205,201),INDEX(LE_Curves!$B$5:$B$205,201),INDEX(LE_Curves!$B$5:$B$205,MATCH($B$9,LE_Curves!$N$5:$N$205,1))+($B$9-INDEX(LE_Curves!$N$5:$N$205,MATCH($B$9,LE_Curves!$N$5:$N$205,1)))*(INDEX(LE_Curves!$B$5:$B$205,MATCH($B$9,LE_Curves!$N$5:$N$205,1)+1)-INDEX(LE_Curves!$B$5:$B$205,MATCH($B$9,LE_Curves!$N$5:$N$205,1)))/(INDEX(LE_Curves!$N$5:$N$205,MATCH($B$9,LE_Curves!$N$5:$N$205,1)+1)-INDEX(LE_Curves!$N$5:$N$205,MATCH($B$9,LE_Curves!$N$5:$N$205,1)))))) | H15: =G15*Inputs!$B$4/$B$10 | I15: =H15/Inputs!$B$4 | J15: =IF(F15>0,Inputs!$B$12*Inputs!$B$5*H15^2/(F15^2*Inputs!H34^4*Inputs!I34^2),0) | K15: =IF(F15>0,Inputs!G34*H15^Inputs!$B$11,0) | L15: =IF(F15>0,H15/Inputs!$B$20-1,0) | M15: =IF(F15>0,H15,1000000000)
A17: P* is found on a 201-point pressure grid, refined once between the bracketing points (grids below, row 30+).
A29: Coarse pressure grid | Q29: Refined grid between bracket points
A30: k | B30: P, MPa | C30: =Inputs!A23 | D30: =Inputs!A24 | E30: =Inputs!A25 | F30: =Inputs!A26 | G30: =Inputs!A27 | H30: =Inputs!A28 | I30: =Inputs!A29 | J30: =Inputs!A30 | K30: =Inputs!A31 | L30: =Inputs!A32 | M30: =Inputs!A33 | N30: =Inputs!A34 | O30: Σq | Q30: k | R30: P fine, MPa | S30: =Inputs!A23 | T30: =Inputs!A24 | U30: =Inputs!A25 | V30: =Inputs!A26 | W30: =Inputs!A27 | X30: =Inputs!A28 | Y30: =Inputs!A29 | Z30: =Inputs!A30 | AA30: =Inputs!A31 | AB30: =Inputs!A32 | AC30: =Inputs!A33 | AD30: =Inputs!A34 | AE30: Σq
A31: 0 | B31: =$B$3+($B$4-$B$3)*A31/200 | C31: =IF(Inputs!$D$23=0,0,IF($B31<=Inputs!$C$23,0,IF($B31>=INDEX(LE_Curves!$C$5:$C$205,201),INDEX(LE_Curves!$B$5:$B$205,201),INDEX(LE_Curves!$B$5:$B$205,MATCH($B31,LE_Curves!$C$5:$C$205,1))+($B31-INDEX(LE_Curves!$C$5:$C$205,MATCH($B31,LE_Curves!$C$5:$C$205,1)))*(INDEX(LE_Curves!$B$5:$B$205,MATCH($B31,LE_Curves!$C$5:$C$205,1)+1)-INDEX(LE_Curves!$B$5:$B$205,MATCH($B31,LE_Curves!$C$5:$C$205,1)))/(INDEX(LE_Curves!$C$5:$C$205,MATCH($B31,LE_Curves!$C$5:$C$205,1)+1)-INDEX(LE_Curves!$C$5:$C$205,MATCH($B31,LE_Curves!$C$5:$C$205,1)))))) | D31: =IF(Inputs!$D$24=0,0,IF($B31<=Inputs!$C$24,0,IF($B31>=INDEX(LE_Curves!$D$5:$D$205,201),INDEX(LE_Curves!$B$5:$B$205,201),INDEX(LE_Curves!$B$5:$B$205,MATCH($B31,LE_Curves!$D$5:$D$205,1))+($B31-INDEX(LE_Curves!$D$5:$D$205,MATCH($B31,LE_Curves!$D$5:$D$205,1)))*(INDEX(LE_Curves!$B$5:$B$205,MATCH($B31,LE_Curves!$D$5:$D$205,1)+1)-INDEX(LE_Curves!$B$5:$B$205,MATCH($B31,LE_Curves!$D$5:$D$205,1)))/(INDEX(LE_Curves!$D$5:$D$205,MATCH($B31,LE_Curves!$D$5:$D$205,1)+1)-INDEX(LE_Curves!$D$5:$D$205,MATCH($B31,LE_Curves!$D$5:$D$205,1)))))) | E31: =IF(Inputs!$D$25=0,0,IF($B31<=Inputs!$C$25,0,IF($B31>=INDEX(LE_Curves!$E$5:$E$205,201),INDEX(LE_Curves!$B$5:$B$205,201),INDEX(LE_Curves!$B$5:$B$205,MATCH($B31,LE_Curves!$E$5:$E$205,1))+($B31-INDEX(LE_Curves!$E$5:$E$205,MATCH($B31,LE_Curves!$E$5:$E$205,1)))*(INDEX(LE_Curves!$B$5:$B$205,MATCH($B31,LE_Curves!$E$5:$E$205,1)+1)-INDEX(LE_Curves!$B$5:$B$205,MATCH($B31,LE_Curves!$E$5:$E$205,1)))/(INDEX(LE_Curves!$E$5:$E$205,MATCH($B31,LE_Curves!$E$5:$E$205,1)+1)-INDEX(LE_Curves!$E$5:$E$205,MATCH($B31,LE_Curves!$E$5:$E$205,1)))))) | F31: =IF(Inputs!$D$26=0,0,IF($B31<=Inputs!$C$26,0,IF($B31>=INDEX(LE_Curves!$F$5:$F$205,201),INDEX(LE_Curves!$B$5:$B$205,201),INDEX(LE_Curves!$B$5:$B$205,MATCH($B31,LE_Curves!$F$5:$F$205,1))+($B31-INDEX(LE_Curves!$F$5:$F$205,MATCH($B31,LE_Curves!$F$5:$F$205,1)))*(INDEX(LE_Curves!$B$5:$B$205,MATCH($B31,LE_Curves!$F$5:$F$205,1)+1)-INDEX(LE_Curves!$B$5:$B$205,MATCH($B31,LE_Curves!$F$5:$F$205,1)))/(INDEX(LE_Curves!$F$5:$F$205,MATCH($B31,LE_Curves!$F$5:$F$205,1)+1)-INDEX(LE_Curves!$F$5:$F$205,MATCH($B31,LE_Curves!$F$5:$F$205,1)))))) | G31: =IF(Inputs!$D$27=0,0,IF($B31<=Inputs!$C$27,0,IF($B31>=INDEX(LE_Curves!$G$5:$G$205,201),INDEX(LE_Curves!$B$5:$B$205,201),INDEX(LE_Curves!$B$5:$B$205,MATCH($B31,LE_Curves!$G$5:$G$205,1))+($B31-INDEX(LE_Curves!$G$5:$G$205,MATCH($B31,LE_Curves!$G$5:$G$205,1)))*(INDEX(LE_Curves!$B$5:$B$205,MATCH($B31,LE_Curves!$G$5:$G$205,1)+1)-INDEX(LE_Curves!$B$5:$B$205,MATCH($B31,LE_Curves!$G$5:$G$205,1)))/(INDEX(LE_Curves!$G$5:$G$205,MATCH($B31,LE_Curves!$G$5:$G$205,1)+1)-INDEX(LE_Curves!$G$5:$G$205,MATCH($B31,LE_Curves!$G$5:$G$205,1)))))) | H31: =IF(Inputs!$D$28=0,0,IF($B31<=Inputs!$C$28,0,IF($B31>=INDEX(LE_Curves!$H$5:$H$205,201),INDEX(LE_Curves!$B$5:$B$205,201),INDEX(LE_Curves!$B$5:$B$205,MATCH($B31,LE_Curves!$H$5:$H$205,1))+($B31-INDEX(LE_Curves!$H$5:$H$205,MATCH($B31,LE_Curves!$H$5:$H$205,1)))*(INDEX(LE_Curves!$B$5:$B$205,MATCH($B31,LE_Curves!$H$5:$H$205,1)+1)-INDEX(LE_Curves!$B$5:$B$205,MATCH($B31,LE_Curves!$H$5:$H$205,1)))/(INDEX(LE_Curves!$H$5:$H$205,MATCH($B31,LE_Curves!$H$5:$H$205,1)+1)-INDEX(LE_Curves!$H$5:$H$205,MATCH($B31,LE_Curves!$H$5:$H$205,1)))))) | I31: =IF(Inputs!$D$29=0,0,IF($B31<=Inputs!$C$29,0,IF($B31>=INDEX(LE_Curves!$I$5:$I$205,201),INDEX(LE_Curves!$B$5:$B$205,201),INDEX(LE_Curves!$B$5:$B$205,MATCH($B31,LE_Curves!$I$5:$I$205,1))+($B31-INDEX(LE_Curves!$I$5:$I$205,MATCH($B31,LE_Curves!$I$5:$I$205,1)))*(INDEX(LE_Curves!$B$5:$B$205,MATCH($B31,LE_Curves!$I$5:$I$205,1)+1)-INDEX(LE_Curves!$B$5:$B$205,MATCH($B31,LE_Curves!$I$5:$I$205,1)))/(INDEX(LE_Curves!$I$5:$I$205,MATCH($B31,LE_Curves!$I$5:$I$205,1)+1)-INDEX(LE_Curves!$I$5:$I$205,MATCH($B31,LE_Curves!$I$5:$I$205,1)))))) | J31: =IF(Inputs!$D$30=0,0,IF($B31<=Inputs!$C$30,0,IF($B31>=INDEX(LE_Curves!$J$5:$J$205,201),INDEX(LE_Curves!$B$5:$B$205,201),INDEX(LE_Curves!$B$5:$B$205,MATCH($B31,LE_Curves!$J$5:$J$205,1))+($B31-INDEX(LE_Curves!$J$5:$J$205,MATCH($B31,LE_Curves!$J$5:$J$205,1)))*(INDEX(LE_Curves!$B$5:$B$205,MATCH($B31,LE_Curves!$J$5:$J$205,1)+1)-INDEX(LE_Curves!$B$5:$B$205,MATCH($B31,LE_Curves!$J$5:$J$205,1)))/(INDEX(LE_Curves!$J$5:$J$205,MATCH($B31,LE_Curves!$J$5:$J$205,1)+1)-INDEX(LE_Curves!$J$5:$J$205,MATCH($B31,LE_Curves!$J$5:$J$205,1)))))) | K31: =IF(Inputs!$D$31=0,0,IF($B31<=Inputs!$C$31,0,IF($B31>=INDEX(LE_Curves!$K$5:$K$205,201),INDEX(LE_Curves!$B$5:$B$205,201),INDEX(LE_Curves!$B$5:$B$205,MATCH($B31,LE_Curves!$K$5:$K$205,1))+($B31-INDEX(LE_Curves!$K$5:$K$205,MATCH($B31,LE_Curves!$K$5:$K$205,1)))*(INDEX(LE_Curves!$B$5:$B$205,MATCH($B31,LE_Curves!$K$5:$K$205,1)+1)-INDEX(LE_Curves!$B$5:$B$205,MATCH($B31,LE_Curves!$K$5:$K$205,1)))/(INDEX(LE_Curves!$K$5:$K$205,MATCH($B31,LE_Curves!$K$5:$K$205,1)+1)-INDEX(LE_Curves!$K$5:$K$205,MATCH($B31,LE_Curves!$K$5:$K$205,1)))))) | L31: =IF(Inputs!$D$32=0,0,IF($B31<=Inputs!$C$32,0,IF($B31>=INDEX(LE_Curves!$L$5:$L$205,201),INDEX(LE_Curves!$B$5:$B$205,201),INDEX(LE_Curves!$B$5:$B$205,MATCH($B31,LE_Curves!$L$5:$L$205,1))+($B31-INDEX(LE_Curves!$L$5:$L$205,MATCH($B31,LE_Curves!$L$5:$L$205,1)))*(INDEX(LE_Curves!$B$5:$B$205,MATCH($B31,LE_Curves!$L$5:$L$205,1)+1)-INDEX(LE_Curves!$B$5:$B$205,MATCH($B31,LE_Curves!$L$5:$L$205,1)))/(INDEX(LE_Curves!$L$5:$L$205,MATCH($B31,LE_Curves!$L$5:$L$205,1)+1)-INDEX(LE_Curves!$L$5:$L$205,MATCH($B31,LE_Curves!$L$5:$L$205,1)))))) | M31: =IF(Inputs!$D$33=0,0,IF($B31<=Inputs!$C$33,0,IF($B31>=INDEX(LE_Curves!$M$5:$M$205,201),INDEX(LE_Curves!$B$5:$B$205,201),INDEX(LE_Curves!$B$5:$B$205,MATCH($B31,LE_Curves!$M$5:$M$205,1))+($B31-INDEX(LE_Curves!$M$5:$M$205,MATCH($B31,LE_Curves!$M$5:$M$205,1)))*(INDEX(LE_Curves!$B$5:$B$205,MATCH($B31,LE_Curves!$M$5:$M$205,1)+1)-INDEX(LE_Curves!$B$5:$B$205,MATCH($B31,LE_Curves!$M$5:$M$205,1)))/(INDEX(LE_Curves!$M$5:$M$205,MATCH($B31,LE_Curves!$M$5:$M$205,1)+1)-INDEX(LE_Curves!$M$5:$M$205,MATCH($B31,LE_Curves!$M$5:$M$205,1)))))) | N31: =IF(Inputs!$D$34=0,0,IF($B31<=Inputs!$C$34,0,IF($B31>=INDEX(LE_Curves!$N$5:$N$205,201),INDEX(LE_Curves!$B$5:$B$205,201),INDEX(LE_Curves!$B$5:$B$205,MATCH($B31,LE_Curves!$N$5:$N$205,1))+($B31-INDEX(LE_Curves!$N$5:$N$205,MATCH($B31,LE_Curves!$N$5:$N$205,1)))*(INDEX(LE_Curves!$B$5:$B$205,MATCH($B31,LE_Curves!$N$5:$N$205,1)+1)-INDEX(LE_Curves!$B$5:$B$205,MATCH($B31,LE_Curves!$N$5:$N$205,1)))/(INDEX(LE_Curves!$N$5:$N$205,MATCH($B31,LE_Curves!$N$5:$N$205,1)+1)-INDEX(LE_Curves!$N$5:$N$205,MATCH($B31,LE_Curves!$N$5:$N$205,1)))))) | O31: =SUM(C31:N31) | Q31: 0 | R31: =$B$6+($B$7-$B$6)*Q31/200 | S31: =IF(Inputs!$D$23=0,0,IF($R31<=Inputs!$C$23,0,IF($R31>=INDEX(LE_Curves!$C$5:$C$205,201),INDEX(LE_Curves!$B$5:$B$205,201),INDEX(LE_Curves!$B$5:$B$205,MATCH($R31,LE_Curves!$C$5:$C$205,1))+($R31-INDEX(LE_Curves!$C$5:$C$205,MATCH($R31,LE_Curves!$C$5:$C$205,1)))*(INDEX(LE_Curves!$B$5:$B$205,MATCH($R31,LE_Curves!$C$5:$C$205,1)+1)-INDEX(LE_Curves!$B$5:$B$205,MATCH($R31,LE_Curves!$C$5:$C$205,1)))/(INDEX(LE_Curves!$C$5:$C$205,MATCH($R31,LE_Curves!$C$5:$C$205,1)+1)-INDEX(LE_Curves!$C$5:$C$205,MATCH($R31,LE_Curves!$C$5:$C$205,1)))))) | T31: =IF(Inputs!$D$24=0,0,IF($R31<=Inputs!$C$24,0,IF($R31>=INDEX(LE_Curves!$D$5:$D$205,201),INDEX(LE_Curves!$B$5:$B$205,201),INDEX(LE_Curves!$B$5:$B$205,MATCH($R31,LE_Curves!$D$5:$D$205,1))+($R31-INDEX(LE_Curves!$D$5:$D$205,MATCH($R31,LE_Curves!$D$5:$D$205,1)))*(INDEX(LE_Curves!$B$5:$B$205,MATCH($R31,LE_Curves!$D$5:$D$205,1)+1)-INDEX(LE_Curves!$B$5:$B$205,MATCH($R31,LE_Curves!$D$5:$D$205,1)))/(INDEX(LE_Curves!$D$5:$D$205,MATCH($R31,LE_Curves!$D$5:$D$205,1)+1)-INDEX(LE_Curves!$D$5:$D$205,MATCH($R31,LE_Curves!$D$5:$D$205,1)))))) | U31: =IF(Inputs!$D$25=0,0,IF($R31<=Inputs!$C$25,0,IF($R31>=INDEX(LE_Curves!$E$5:$E$205,201),INDEX(LE_Curves!$B$5:$B$205,201),INDEX(LE_Curves!$B$5:$B$205,MATCH($R31,LE_Curves!$E$5:$E$205,1))+($R31-INDEX(LE_Curves!$E$5:$E$205,MATCH($R31,LE_Curves!$E$5:$E$205,1)))*(INDEX(LE_Curves!$B$5:$B$205,MATCH($R31,LE_Curves!$E$5:$E$205,1)+1)-INDEX(LE_Curves!$B$5:$B$205,MATCH($R31,LE_Curves!$E$5:$E$205,1)))/(INDEX(LE_Curves!$E$5:$E$205,MATCH($R31,LE_Curves!$E$5:$E$205,1)+1)-INDEX(LE_Curves!$E$5:$E$205,MATCH($R31,LE_Curves!$E$5:$E$205,1)))))) | V31: =IF(Inputs!$D$26=0,0,IF($R31<=Inputs!$C$26,0,IF($R31>=INDEX(LE_Curves!$F$5:$F$205,201),INDEX(LE_Curves!$B$5:$B$205,201),INDEX(LE_Curves!$B$5:$B$205,MATCH($R31,LE_Curves!$F$5:$F$205,1))+($R31-INDEX(LE_Curves!$F$5:$F$205,MATCH($R31,LE_Curves!$F$5:$F$205,1)))*(INDEX(LE_Curves!$B$5:$B$205,MATCH($R31,LE_Curves!$F$5:$F$205,1)+1)-INDEX(LE_Curves!$B$5:$B$205,MATCH($R31,LE_Curves!$F$5:$F$205,1)))/(INDEX(LE_Curves!$F$5:$F$205,MATCH($R31,LE_Curves!$F$5:$F$205,1)+1)-INDEX(LE_Curves!$F$5:$F$205,MATCH($R31,LE_Curves!$F$5:$F$205,1)))))) | W31: =IF(Inputs!$D$27=0,0,IF($R31<=Inputs!$C$27,0,IF($R31>=INDEX(LE_Curves!$G$5:$G$205,201),INDEX(LE_Curves!$B$5:$B$205,201),INDEX(LE_Curves!$B$5:$B$205,MATCH($R31,LE_Curves!$G$5:$G$205,1))+($R31-INDEX(LE_Curves!$G$5:$G$205,MATCH($R31,LE_Curves!$G$5:$G$205,1)))*(INDEX(LE_Curves!$B$5:$B$205,MATCH($R31,LE_Curves!$G$5:$G$205,1)+1)-INDEX(LE_Curves!$B$5:$B$205,MATCH($R31,LE_Curves!$G$5:$G$205,1)))/(INDEX(LE_Curves!$G$5:$G$205,MATCH($R31,LE_Curves!$G$5:$G$205,1)+1)-INDEX(LE_Curves!$G$5:$G$205,MATCH($R31,LE_Curves!$G$5:$G$205,1)))))) | X31: =IF(Inputs!$D$28=0,0,IF($R31<=Inputs!$C$28,0,IF($R31>=INDEX(LE_Curves!$H$5:$H$205,201),INDEX(LE_Curves!$B$5:$B$205,201),INDEX(LE_Curves!$B$5:$B$205,MATCH($R31,LE_Curves!$H$5:$H$205,1))+($R31-INDEX(LE_Curves!$H$5:$H$205,MATCH($R31,LE_Curves!$H$5:$H$205,1)))*(INDEX(LE_Curves!$B$5:$B$205,MATCH($R31,LE_Curves!$H$5:$H$205,1)+1)-INDEX(LE_Curves!$B$5:$B$205,MATCH($R31,LE_Curves!$H$5:$H$205,1)))/(INDEX(LE_Curves!$H$5:$H$205,MATCH($R31,LE_Curves!$H$5:$H$205,1)+1)-INDEX(LE_Curves!$H$5:$H$205,MATCH($R31,LE_Curves!$H$5:$H$205,1)))))) | Y31: =IF(Inputs!$D$29=0,0,IF($R31<=Inputs!$C$29,0,IF($R31>=INDEX(LE_Curves!$I$5:$I$205,201),INDEX(LE_Curves!$B$5:$B$205,201),INDEX(LE_Curves!$B$5:$B$205,MATCH($R31,LE_Curves!$I$5:$I$205,1))+($R31-INDEX(LE_Curves!$I$5:$I$205,MATCH($R31,LE_Curves!$I$5:$I$205,1)))*(INDEX(LE_Curves!$B$5:$B$205,MATCH($R31,LE_Curves!$I$5:$I$205,1)+1)-INDEX(LE_Curves!$B$5:$B$205,MATCH($R31,LE_Curves!$I$5:$I$205,1)))/(INDEX(LE_Curves!$I$5:$I$205,MATCH($R31,LE_Curves!$I$5:$I$205,1)+1)-INDEX(LE_Curves!$I$5:$I$205,MATCH($R31,LE_Curves!$I$5:$I$205,1)))))) | Z31: =IF(Inputs!$D$30=0,0,IF($R31<=Inputs!$C$30,0,IF($R31>=INDEX(LE_Curves!$J$5:$J$205,201),INDEX(LE_Curves!$B$5:$B$205,201),INDEX(LE_Curves!$B$5:$B$205,MATCH($R31,LE_Curves!$J$5:$J$205,1))+($R31-INDEX(LE_Curves!$J$5:$J$205,MATCH($R31,LE_Curves!$J$5:$J$205,1)))*(INDEX(LE_Curves!$B$5:$B$205,MATCH($R31,LE_Curves!$J$5:$J$205,1)+1)-INDEX(LE_Curves!$B$5:$B$205,MATCH($R31,LE_Curves!$J$5:$J$205,1)))/(INDEX(LE_Curves!$J$5:$J$205,MATCH($R31,LE_Curves!$J$5:$J$205,1)+1)-INDEX(LE_Curves!$J$5:$J$205,MATCH($R31,LE_Curves!$J$5:$J$205,1)))))) | AA31: =IF(Inputs!$D$31=0,0,IF($R31<=Inputs!$C$31,0,IF($R31>=INDEX(LE_Curves!$K$5:$K$205,201),INDEX(LE_Curves!$B$5:$B$205,201),INDEX(LE_Curves!$B$5:$B$205,MATCH($R31,LE_Curves!$K$5:$K$205,1))+($R31-INDEX(LE_Curves!$K$5:$K$205,MATCH($R31,LE_Curves!$K$5:$K$205,1)))*(INDEX(LE_Curves!$B$5:$B$205,MATCH($R31,LE_Curves!$K$5:$K$205,1)+1)-INDEX(LE_Curves!$B$5:$B$205,MATCH($R31,LE_Curves!$K$5:$K$205,1)))/(INDEX(LE_Curves!$K$5:$K$205,MATCH($R31,LE_Curves!$K$5:$K$205,1)+1)-INDEX(LE_Curves!$K$5:$K$205,MATCH($R31,LE_Curves!$K$5:$K$205,1)))))) | AB31: =IF(Inputs!$D$32=0,0,IF($R31<=Inputs!$C$32,0,IF($R31>=INDEX(LE_Curves!$L$5:$L$205,201),INDEX(LE_Curves!$B$5:$B$205,201),INDEX(LE_Curves!$B$5:$B$205,MATCH($R31,LE_Curves!$L$5:$L$205,1))+($R31-INDEX(LE_Curves!$L$5:$L$205,MATCH($R31,LE_Curves!$L$5:$L$205,1)))*(INDEX(LE_Curves!$B$5:$B$205,MATCH($R31,LE_Curves!$L$5:$L$205,1)+1)-INDEX(LE_Curves!$B$5:$B$205,MATCH($R31,LE_Curves!$L$5:$L$205,1)))/(INDEX(LE_Curves!$L$5:$L$205,MATCH($R31,LE_Curves!$L$5:$L$205,1)+1)-INDEX(LE_Curves!$L$5:$L$205,MATCH($R31,LE_Curves!$L$5:$L$205,1)))))) | AC31: =IF(Inputs!$D$33=0,0,IF($R31<=Inputs!$C$33,0,IF($R31>=INDEX(LE_Curves!$M$5:$M$205,201),INDEX(LE_Curves!$B$5:$B$205,201),INDEX(LE_Curves!$B$5:$B$205,MATCH($R31,LE_Curves!$M$5:$M$205,1))+($R31-INDEX(LE_Curves!$M$5:$M$205,MATCH($R31,LE_Curves!$M$5:$M$205,1)))*(INDEX(LE_Curves!$B$5:$B$205,MATCH($R31,LE_Curves!$M$5:$M$205,1)+1)-INDEX(LE_Curves!$B$5:$B$205,MATCH($R31,LE_Curves!$M$5:$M$205,1)))/(INDEX(LE_Curves!$M$5:$M$205,MATCH($R31,LE_Curves!$M$5:$M$205,1)+1)-INDEX(LE_Curves!$M$5:$M$205,MATCH($R31,LE_Curves!$M$5:$M$205,1)))))) | AD31: =IF(Inputs!$D$34=0,0,IF($R31<=Inputs!$C$34,0,IF($R31>=INDEX(LE_Curves!$N$5:$N$205,201),INDEX(LE_Curves!$B$5:$B$205,201),INDEX(LE_Curves!$B$5:$B$205,MATCH($R31,LE_Curves!$N$5:$N$205,1))+($R31-INDEX(LE_Curves!$N$5:$N$205,MATCH($R31,LE_Curves!$N$5:$N$205,1)))*(INDEX(LE_Curves!$B$5:$B$205,MATCH($R31,LE_Curves!$N$5:$N$205,1)+1)-INDEX(LE_Curves!$B$5:$B$205,MATCH($R31,LE_Curves!$N$5:$N$205,1)))/(INDEX(LE_Curves!$N$5:$N$205,MATCH($R31,LE_Curves!$N$5:$N$205,1)+1)-INDEX(LE_Curves!$N$5:$N$205,MATCH($R31,LE_Curves!$N$5:$N$205,1)))))) | AE31: =SUM(S31:AD31)
A32: 1 | B32: =$B$3+($B$4-$B$3)*A32/200 | C32: =IF(Inputs!$D$23=0,0,IF($B32<=Inputs!$C$23,0,IF($B32>=INDEX(LE_Curves!$C$5:$C$205,201),INDEX(LE_Curves!$B$5:$B$205,201),INDEX(LE_Curves!$B$5:$B$205,MATCH($B32,LE_Curves!$C$5:$C$205,1))+($B32-INDEX(LE_Curves!$C$5:$C$205,MATCH($B32,LE_Curves!$C$5:$C$205,1)))*(INDEX(LE_Curves!$B$5:$B$205,MATCH($B32,LE_Curves!$C$5:$C$205,1)+1)-INDEX(LE_Curves!$B$5:$B$205,MATCH($B32,LE_Curves!$C$5:$C$205,1)))/(INDEX(LE_Curves!$C$5:$C$205,MATCH($B32,LE_Curves!$C$5:$C$205,1)+1)-INDEX(LE_Curves!$C$5:$C$205,MATCH($B32,LE_Curves!$C$5:$C$205,1)))))) | D32: =IF(Inputs!$D$24=0,0,IF($B32<=Inputs!$C$24,0,IF($B32>=INDEX(LE_Curves!$D$5:$D$205,201),INDEX(LE_Curves!$B$5:$B$205,201),INDEX(LE_Curves!$B$5:$B$205,MATCH($B32,LE_Curves!$D$5:$D$205,1))+($B32-INDEX(LE_Curves!$D$5:$D$205,MATCH($B32,LE_Curves!$D$5:$D$205,1)))*(INDEX(LE_Curves!$B$5:$B$205,MATCH($B32,LE_Curves!$D$5:$D$205,1)+1)-INDEX(LE_Curves!$B$5:$B$205,MATCH($B32,LE_Curves!$D$5:$D$205,1)))/(INDEX(LE_Curves!$D$5:$D$205,MATCH($B32,LE_Curves!$D$5:$D$205,1)+1)-INDEX(LE_Curves!$D$5:$D$205,MATCH($B32,LE_Curves!$D$5:$D$205,1)))))) | E32: =IF(Inputs!$D$25=0,0,IF($B32<=Inputs!$C$25,0,IF($B32>=INDEX(LE_Curves!$E$5:$E$205,201),INDEX(LE_Curves!$B$5:$B$205,201),INDEX(LE_Curves!$B$5:$B$205,MATCH($B32,LE_Curves!$E$5:$E$205,1))+($B32-INDEX(LE_Curves!$E$5:$E$205,MATCH($B32,LE_Curves!$E$5:$E$205,1)))*(INDEX(LE_Curves!$B$5:$B$205,MATCH($B32,LE_Curves!$E$5:$E$205,1)+1)-INDEX(LE_Curves!$B$5:$B$205,MATCH($B32,LE_Curves!$E$5:$E$205,1)))/(INDEX(LE_Curves!$E$5:$E$205,MATCH($B32,LE_Curves!$E$5:$E$205,1)+1)-INDEX(LE_Curves!$E$5:$E$205,MATCH($B32,LE_Curves!$E$5:$E$205,1)))))) | F32: =IF(Inputs!$D$26=0,0,IF($B32<=Inputs!$C$26,0,IF($B32>=INDEX(LE_Curves!$F$5:$F$205,201),INDEX(LE_Curves!$B$5:$B$205,201),INDEX(LE_Curves!$B$5:$B$205,MATCH($B32,LE_Curves!$F$5:$F$205,1))+($B32-INDEX(LE_Curves!$F$5:$F$205,MATCH($B32,LE_Curves!$F$5:$F$205,1)))*(INDEX(LE_Curves!$B$5:$B$205,MATCH($B32,LE_Curves!$F$5:$F$205,1)+1)-INDEX(LE_Curves!$B$5:$B$205,MATCH($B32,LE_Curves!$F$5:$F$205,1)))/(INDEX(LE_Curves!$F$5:$F$205,MATCH($B32,LE_Curves!$F$5:$F$205,1)+1)-INDEX(LE_Curves!$F$5:$F$205,MATCH($B32,LE_Curves!$F$5:$F$205,1)))))) | G32: =IF(Inputs!$D$27=0,0,IF($B32<=Inputs!$C$27,0,IF($B32>=INDEX(LE_Curves!$G$5:$G$205,201),INDEX(LE_Curves!$B$5:$B$205,201),INDEX(LE_Curves!$B$5:$B$205,MATCH($B32,LE_Curves!$G$5:$G$205,1))+($B32-INDEX(LE_Curves!$G$5:$G$205,MATCH($B32,LE_Curves!$G$5:$G$205,1)))*(INDEX(LE_Curves!$B$5:$B$205,MATCH($B32,LE_Curves!$G$5:$G$205,1)+1)-INDEX(LE_Curves!$B$5:$B$205,MATCH($B32,LE_Curves!$G$5:$G$205,1)))/(INDEX(LE_Curves!$G$5:$G$205,MATCH($B32,LE_Curves!$G$5:$G$205,1)+1)-INDEX(LE_Curves!$G$5:$G$205,MATCH($B32,LE_Curves!$G$5:$G$205,1)))))) | H32: =IF(Inputs!$D$28=0,0,IF($B32<=Inputs!$C$28,0,IF($B32>=INDEX(LE_Curves!$H$5:$H$205,201),INDEX(LE_Curves!$B$5:$B$205,201),INDEX(LE_Curves!$B$5:$B$205,MATCH($B32,LE_Curves!$H$5:$H$205,1))+($B32-INDEX(LE_Curves!$H$5:$H$205,MATCH($B32,LE_Curves!$H$5:$H$205,1)))*(INDEX(LE_Curves!$B$5:$B$205,MATCH($B32,LE_Curves!$H$5:$H$205,1)+1)-INDEX(LE_Curves!$B$5:$B$205,MATCH($B32,LE_Curves!$H$5:$H$205,1)))/(INDEX(LE_Curves!$H$5:$H$205,MATCH($B32,LE_Curves!$H$5:$H$205,1)+1)-INDEX(LE_Curves!$H$5:$H$205,MATCH($B32,LE_Curves!$H$5:$H$205,1)))))) | I32: =IF(Inputs!$D$29=0,0,IF($B32<=Inputs!$C$29,0,IF($B32>=INDEX(LE_Curves!$I$5:$I$205,201),INDEX(LE_Curves!$B$5:$B$205,201),INDEX(LE_Curves!$B$5:$B$205,MATCH($B32,LE_Curves!$I$5:$I$205,1))+($B32-INDEX(LE_Curves!$I$5:$I$205,MATCH($B32,LE_Curves!$I$5:$I$205,1)))*(INDEX(LE_Curves!$B$5:$B$205,MATCH($B32,LE_Curves!$I$5:$I$205,1)+1)-INDEX(LE_Curves!$B$5:$B$205,MATCH($B32,LE_Curves!$I$5:$I$205,1)))/(INDEX(LE_Curves!$I$5:$I$205,MATCH($B32,LE_Curves!$I$5:$I$205,1)+1)-INDEX(LE_Curves!$I$5:$I$205,MATCH($B32,LE_Curves!$I$5:$I$205,1)))))) | J32: =IF(Inputs!$D$30=0,0,IF($B32<=Inputs!$C$30,0,IF($B32>=INDEX(LE_Curves!$J$5:$J$205,201),INDEX(LE_Curves!$B$5:$B$205,201),INDEX(LE_Curves!$B$5:$B$205,MATCH($B32,LE_Curves!$J$5:$J$205,1))+($B32-INDEX(LE_Curves!$J$5:$J$205,MATCH($B32,LE_Curves!$J$5:$J$205,1)))*(INDEX(LE_Curves!$B$5:$B$205,MATCH($B32,LE_Curves!$J$5:$J$205,1)+1)-INDEX(LE_Curves!$B$5:$B$205,MATCH($B32,LE_Curves!$J$5:$J$205,1)))/(INDEX(LE_Curves!$J$5:$J$205,MATCH($B32,LE_Curves!$J$5:$J$205,1)+1)-INDEX(LE_Curves!$J$5:$J$205,MATCH($B32,LE_Curves!$J$5:$J$205,1)))))) | K32: =IF(Inputs!$D$31=0,0,IF($B32<=Inputs!$C$31,0,IF($B32>=INDEX(LE_Curves!$K$5:$K$205,201),INDEX(LE_Curves!$B$5:$B$205,201),INDEX(LE_Curves!$B$5:$B$205,MATCH($B32,LE_Curves!$K$5:$K$205,1))+($B32-INDEX(LE_Curves!$K$5:$K$205,MATCH($B32,LE_Curves!$K$5:$K$205,1)))*(INDEX(LE_Curves!$B$5:$B$205,MATCH($B32,LE_Curves!$K$5:$K$205,1)+1)-INDEX(LE_Curves!$B$5:$B$205,MATCH($B32,LE_Curves!$K$5:$K$205,1)))/(INDEX(LE_Curves!$K$5:$K$205,MATCH($B32,LE_Curves!$K$5:$K$205,1)+1)-INDEX(LE_Curves!$K$5:$K$205,MATCH($B32,LE_Curves!$K$5:$K$205,1)))))) | L32: =IF(Inputs!$D$32=0,0,IF($B32<=Inputs!$C$32,0,IF($B32>=INDEX(LE_Curves!$L$5:$L$205,201),INDEX(LE_Curves!$B$5:$B$205,201),INDEX(LE_Curves!$B$5:$B$205,MATCH($B32,LE_Curves!$L$5:$L$205,1))+($B32-INDEX(LE_Curves!$L$5:$L$205,MATCH($B32,LE_Curves!$L$5:$L$205,1)))*(INDEX(LE_Curves!$B$5:$B$205,MATCH($B32,LE_Curves!$L$5:$L$205,1)+1)-INDEX(LE_Curves!$B$5:$B$205,MATCH($B32,LE_Curves!$L$5:$L$205,1)))/(INDEX(LE_Curves!$L$5:$L$205,MATCH($B32,LE_Curves!$L$5:$L$205,1)+1)-INDEX(LE_Curves!$L$5:$L$205,MATCH($B32,LE_Curves!$L$5:$L$205,1)))))) | M32: =IF(Inputs!$D$33=0,0,IF($B32<=Inputs!$C$33,0,IF($B32>=INDEX(LE_Curves!$M$5:$M$205,201),INDEX(LE_Curves!$B$5:$B$205,201),INDEX(LE_Curves!$B$5:$B$205,MATCH($B32,LE_Curves!$M$5:$M$205,1))+($B32-INDEX(LE_Curves!$M$5:$M$205,MATCH($B32,LE_Curves!$M$5:$M$205,1)))*(INDEX(LE_Curves!$B$5:$B$205,MATCH($B32,LE_Curves!$M$5:$M$205,1)+1)-INDEX(LE_Curves!$B$5:$B$205,MATCH($B32,LE_Curves!$M$5:$M$205,1)))/(INDEX(LE_Curves!$M$5:$M$205,MATCH($B32,LE_Curves!$M$5:$M$205,1)+1)-INDEX(LE_Curves!$M$5:$M$205,MATCH($B32,LE_Curves!$M$5:$M$205,1)))))) | N32: =IF(Inputs!$D$34=0,0,IF($B32<=Inputs!$C$34,0,IF($B32>=INDEX(LE_Curves!$N$5:$N$205,201),INDEX(LE_Curves!$B$5:$B$205,201),INDEX(LE_Curves!$B$5:$B$205,MATCH($B32,LE_Curves!$N$5:$N$205,1))+($B32-INDEX(LE_Curves!$N$5:$N$205,MATCH($B32,LE_Curves!$N$5:$N$205,1)))*(INDEX(LE_Curves!$B$5:$B$205,MATCH($B32,LE_Curves!$N$5:$N$205,1)+1)-INDEX(LE_Curves!$B$5:$B$205,MATCH($B32,LE_Curves!$N$5:$N$205,1)))/(INDEX(LE_Curves!$N$5:$N$205,MATCH($B32,LE_Curves!$N$5:$N$205,1)+1)-INDEX(LE_Curves!$N$5:$N$205,MATCH($B32,LE_Curves!$N$5:$N$205,1)))))) | O32: =SUM(C32:N32) | Q32: 1 | R32: =$B$6+($B$7-$B$6)*Q32/200 | S32: =IF(Inputs!$D$23=0,0,IF($R32<=Inputs!$C$23,0,IF($R32>=INDEX(LE_Curves!$C$5:$C$205,201),INDEX(LE_Curves!$B$5:$B$205,201),INDEX(LE_Curves!$B$5:$B$205,MATCH($R32,LE_Curves!$C$5:$C$205,1))+($R32-INDEX(LE_Curves!$C$5:$C$205,MATCH($R32,LE_Curves!$C$5:$C$205,1)))*(INDEX(LE_Curves!$B$5:$B$205,MATCH($R32,LE_Curves!$C$5:$C$205,1)+1)-INDEX(LE_Curves!$B$5:$B$205,MATCH($R32,LE_Curves!$C$5:$C$205,1)))/(INDEX(LE_Curves!$C$5:$C$205,MATCH($R32,LE_Curves!$C$5:$C$205,1)+1)-INDEX(LE_Curves!$C$5:$C$205,MATCH($R32,LE_Curves!$C$5:$C$205,1)))))) | T32: =IF(Inputs!$D$24=0,0,IF($R32<=Inputs!$C$24,0,IF($R32>=INDEX(LE_Curves!$D$5:$D$205,201),INDEX(LE_Curves!$B$5:$B$205,201),INDEX(LE_Curves!$B$5:$B$205,MATCH($R32,LE_Curves!$D$5:$D$205,1))+($R32-INDEX(LE_Curves!$D$5:$D$205,MATCH($R32,LE_Curves!$D$5:$D$205,1)))*(INDEX(LE_Curves!$B$5:$B$205,MATCH($R32,LE_Curves!$D$5:$D$205,1)+1)-INDEX(LE_Curves!$B$5:$B$205,MATCH($R32,LE_Curves!$D$5:$D$205,1)))/(INDEX(LE_Curves!$D$5:$D$205,MATCH($R32,LE_Curves!$D$5:$D$205,1)+1)-INDEX(LE_Curves!$D$5:$D$205,MATCH($R32,LE_Curves!$D$5:$D$205,1)))))) | U32: =IF(Inputs!$D$25=0,0,IF($R32<=Inputs!$C$25,0,IF($R32>=INDEX(LE_Curves!$E$5:$E$205,201),INDEX(LE_Curves!$B$5:$B$205,201),INDEX(LE_Curves!$B$5:$B$205,MATCH($R32,LE_Curves!$E$5:$E$205,1))+($R32-INDEX(LE_Curves!$E$5:$E$205,MATCH($R32,LE_Curves!$E$5:$E$205,1)))*(INDEX(LE_Curves!$B$5:$B$205,MATCH($R32,LE_Curves!$E$5:$E$205,1)+1)-INDEX(LE_Curves!$B$5:$B$205,MATCH($R32,LE_Curves!$E$5:$E$205,1)))/(INDEX(LE_Curves!$E$5:$E$205,MATCH($R32,LE_Curves!$E$5:$E$205,1)+1)-INDEX(LE_Curves!$E$5:$E$205,MATCH($R32,LE_Curves!$E$5:$E$205,1)))))) | V32: =IF(Inputs!$D$26=0,0,IF($R32<=Inputs!$C$26,0,IF($R32>=INDEX(LE_Curves!$F$5:$F$205,201),INDEX(LE_Curves!$B$5:$B$205,201),INDEX(LE_Curves!$B$5:$B$205,MATCH($R32,LE_Curves!$F$5:$F$205,1))+($R32-INDEX(LE_Curves!$F$5:$F$205,MATCH($R32,LE_Curves!$F$5:$F$205,1)))*(INDEX(LE_Curves!$B$5:$B$205,MATCH($R32,LE_Curves!$F$5:$F$205,1)+1)-INDEX(LE_Curves!$B$5:$B$205,MATCH($R32,LE_Curves!$F$5:$F$205,1)))/(INDEX(LE_Curves!$F$5:$F$205,MATCH($R32,LE_Curves!$F$5:$F$205,1)+1)-INDEX(LE_Curves!$F$5:$F$205,MATCH($R32,LE_Curves!$F$5:$F$205,1)))))) | W32: =IF(Inputs!$D$27=0,0,IF($R32<=Inputs!$C$27,0,IF($R32>=INDEX(LE_Curves!$G$5:$G$205,201),INDEX(LE_Curves!$B$5:$B$205,201),INDEX(LE_Curves!$B$5:$B$205,MATCH($R32,LE_Curves!$G$5:$G$205,1))+($R32-INDEX(LE_Curves!$G$5:$G$205,MATCH($R32,LE_Curves!$G$5:$G$205,1)))*(INDEX(LE_Curves!$B$5:$B$205,MATCH($R32,LE_Curves!$G$5:$G$205,1)+1)-INDEX(LE_Curves!$B$5:$B$205,MATCH($R32,LE_Curves!$G$5:$G$205,1)))/(INDEX(LE_Curves!$G$5:$G$205,MATCH($R32,LE_Curves!$G$5:$G$205,1)+1)-INDEX(LE_Curves!$G$5:$G$205,MATCH($R32,LE_Curves!$G$5:$G$205,1)))))) | X32: =IF(Inputs!$D$28=0,0,IF($R32<=Inputs!$C$28,0,IF($R32>=INDEX(LE_Curves!$H$5:$H$205,201),INDEX(LE_Curves!$B$5:$B$205,201),INDEX(LE_Curves!$B$5:$B$205,MATCH($R32,LE_Curves!$H$5:$H$205,1))+($R32-INDEX(LE_Curves!$H$5:$H$205,MATCH($R32,LE_Curves!$H$5:$H$205,1)))*(INDEX(LE_Curves!$B$5:$B$205,MATCH($R32,LE_Curves!$H$5:$H$205,1)+1)-INDEX(LE_Curves!$B$5:$B$205,MATCH($R32,LE_Curves!$H$5:$H$205,1)))/(INDEX(LE_Curves!$H$5:$H$205,MATCH($R32,LE_Curves!$H$5:$H$205,1)+1)-INDEX(LE_Curves!$H$5:$H$205,MATCH($R32,LE_Curves!$H$5:$H$205,1)))))) | Y32: =IF(Inputs!$D$29=0,0,IF($R32<=Inputs!$C$29,0,IF($R32>=INDEX(LE_Curves!$I$5:$I$205,201),INDEX(LE_Curves!$B$5:$B$205,201),INDEX(LE_Curves!$B$5:$B$205,MATCH($R32,LE_Curves!$I$5:$I$205,1))+($R32-INDEX(LE_Curves!$I$5:$I$205,MATCH($R32,LE_Curves!$I$5:$I$205,1)))*(INDEX(LE_Curves!$B$5:$B$205,MATCH($R32,LE_Curves!$I$5:$I$205,1)+1)-INDEX(LE_Curves!$B$5:$B$205,MATCH($R32,LE_Curves!$I$5:$I$205,1)))/(INDEX(LE_Curves!$I$5:$I$205,MATCH($R32,LE_Curves!$I$5:$I$205,1)+1)-INDEX(LE_Curves!$I$5:$I$205,MATCH($R32,LE_Curves!$I$5:$I$205,1)))))) | Z32: =IF(Inputs!$D$30=0,0,IF($R32<=Inputs!$C$30,0,IF($R32>=INDEX(LE_Curves!$J$5:$J$205,201),INDEX(LE_Curves!$B$5:$B$205,201),INDEX(LE_Curves!$B$5:$B$205,MATCH($R32,LE_Curves!$J$5:$J$205,1))+($R32-INDEX(LE_Curves!$J$5:$J$205,MATCH($R32,LE_Curves!$J$5:$J$205,1)))*(INDEX(LE_Curves!$B$5:$B$205,MATCH($R32,LE_Curves!$J$5:$J$205,1)+1)-INDEX(LE_Curves!$B$5:$B$205,MATCH($R32,LE_Curves!$J$5:$J$205,1)))/(INDEX(LE_Curves!$J$5:$J$205,MATCH($R32,LE_Curves!$J$5:$J$205,1)+1)-INDEX(LE_Curves!$J$5:$J$205,MATCH($R32,LE_Curves!$J$5:$J$205,1)))))) | AA32: =IF(Inputs!$D$31=0,0,IF($R32<=Inputs!$C$31,0,IF($R32>=INDEX(LE_Curves!$K$5:$K$205,201),INDEX(LE_Curves!$B$5:$B$205,201),INDEX(LE_Curves!$B$5:$B$205,MATCH($R32,LE_Curves!$K$5:$K$205,1))+($R32-INDEX(LE_Curves!$K$5:$K$205,MATCH($R32,LE_Curves!$K$5:$K$205,1)))*(INDEX(LE_Curves!$B$5:$B$205,MATCH($R32,LE_Curves!$K$5:$K$205,1)+1)-INDEX(LE_Curves!$B$5:$B$205,MATCH($R32,LE_Curves!$K$5:$K$205,1)))/(INDEX(LE_Curves!$K$5:$K$205,MATCH($R32,LE_Curves!$K$5:$K$205,1)+1)-INDEX(LE_Curves!$K$5:$K$205,MATCH($R32,LE_Curves!$K$5:$K$205,1)))))) | AB32: =IF(Inputs!$D$32=0,0,IF($R32<=Inputs!$C$32,0,IF($R32>=INDEX(LE_Curves!$L$5:$L$205,201),INDEX(LE_Curves!$B$5:$B$205,201),INDEX(LE_Curves!$B$5:$B$205,MATCH($R32,LE_Curves!$L$5:$L$205,1))+($R32-INDEX(LE_Curves!$L$5:$L$205,MATCH($R32,LE_Curves!$L$5:$L$205,1)))*(INDEX(LE_Curves!$B$5:$B$205,MATCH($R32,LE_Curves!$L$5:$L$205,1)+1)-INDEX(LE_Curves!$B$5:$B$205,MATCH($R32,LE_Curves!$L$5:$L$205,1)))/(INDEX(LE_Curves!$L$5:$L$205,MATCH($R32,LE_Curves!$L$5:$L$205,1)+1)-INDEX(LE_Curves!$L$5:$L$205,MATCH($R32,LE_Curves!$L$5:$L$205,1)))))) | AC32: =IF(Inputs!$D$33=0,0,IF($R32<=Inputs!$C$33,0,IF($R32>=INDEX(LE_Curves!$M$5:$M$205,201),INDEX(LE_Curves!$B$5:$B$205,201),INDEX(LE_Curves!$B$5:$B$205,MATCH($R32,LE_Curves!$M$5:$M$205,1))+($R32-INDEX(LE_Curves!$M$5:$M$205,MATCH($R32,LE_Curves!$M$5:$M$205,1)))*(INDEX(LE_Curves!$B$5:$B$205,MATCH($R32,LE_Curves!$M$5:$M$205,1)+1)-INDEX(LE_Curves!$B$5:$B$205,MATCH($R32,LE_Curves!$M$5:$M$205,1)))/(INDEX(LE_Curves!$M$5:$M$205,MATCH($R32,LE_Curves!$M$5:$M$205,1)+1)-INDEX(LE_Curves!$M$5:$M$205,MATCH($R32,LE_Curves!$M$5:$M$205,1)))))) | AD32: =IF(Inputs!$D$34=0,0,IF($R32<=Inputs!$C$34,0,IF($R32>=INDEX(LE_Curves!$N$5:$N$205,201),INDEX(LE_Curves!$B$5:$B$205,201),INDEX(LE_Curves!$B$5:$B$205,MATCH($R32,LE_Curves!$N$5:$N$205,1))+($R32-INDEX(LE_Curves!$N$5:$N$205,MATCH($R32,LE_Curves!$N$5:$N$205,1)))*(INDEX(LE_Curves!$B$5:$B$205,MATCH($R32,LE_Curves!$N$5:$N$205,1)+1)-INDEX(LE_Curves!$B$5:$B$205,MATCH($R32,LE_Curves!$N$5:$N$205,1)))/(INDEX(LE_Curves!$N$5:$N$205,MATCH($R32,LE_Curves!$N$5:$N$205,1)+1)-INDEX(LE_Curves!$N$5:$N$205,MATCH($R32,LE_Curves!$N$5:$N$205,1)))))) | AE32: =SUM(S32:AD32)
